Workbook

Sheet Intro
C1: Original language | G1: Translated
B2: Name of Complete Course
B3: Name of Free Online Training
B5: Timetable
B6: Beginnig of Promotion (BoP) | C6: 46266
B7: Start Summit | C7: =C6+13
B8: Beginning of Sales (BoS) | C8: =C7+2
B9: End of Sales (EoS) | C9: =C6+26
B10: End of extended Sales (EoeS)
B12: General Information
B13: Domain Name (URL) | C13: https://www.flowsummitespanol.com/
B14: Project Code | C14: flow-cc-s7-l1
B16: Main offer title | C16: Value | E16: Total Value | F16: Price
B17: Your 10-Step Online Learning Material All the shamanic wisdom and teachings, exercises, instructions and meditations packed into an exciting online course! | E17: Our regular price | G17: Update pricing for your country
B18: Audiobook Download the complete course audios and listen to the course where- and whenever you like! | E18: Special Price
B19: Course Workbook The complete workbook to accompany you on your learning journey! Complete with additional information, exercises and summaries. | E19: Installment Price
B20: Your Personal Dream Diary Track your dreams, analyze them and keep up with your progress in this journal! | E20: instead of:
B22: Additional bonus material
B23: Exclusive Documentation: "Shaman Healer Sage" You get exclusive access to this unique documentation in which you will get to know about the master shamans, their work and their way of seeing the world!
B24: Illumnication of the Chakras
B25: Reclaiming your Highest Self - In this Keynote Contribution, Alberto Villoldo takes you on a meditative journey reclaim your birthright and to connect with higher spirit.
B26: Bonus Video: Soul Retrieval Ritual In this exclusive video you will be introduced to the unique shamanic practice of soul retrieval!
B27: Growing a new body - Together with Dr. Mark Hyman, Alberto Villoldo shows you how you can develop the ability du control your own biology and grow a new body through the lense of science and shamanism
B28: 2 Live Call Recordings with Alberto Villoldo answering some of the most important Questions during the Program
B29: 2 live group coaching sessions - The course program includes 2 live online calls with a Master Teacher of the Four Winds Faculty, where your questions that you have about the course will be answered.

Sheet Video List
B1: flow! summit 2026 | C1: Duration | D1: Word count | E1: Character count (with blank spaces) | F1: Voice (Male / Female) | G1: Source | H1: Platform
B2: Main Dropbox Folder | C2: https://www.dropbox.com/scl/fo/qiriyisbn5hfqrasgzzfs/AJVaQ9yLnjZcedu2kie6qMw?rlkey=fesyfl3tynhwz2ac2t4uos21x&st=vdb8u24z&dl=0
B3: Marketing Material | C3: =SUM(C4:C8) | D3: =SUM(D4:D8) | E3: =SUM(E4:E8)
A4: 1 | B4: Trailer | C4: 0 | G4: - | H4: Website
A5: 2 | B5: Snippet 1 | C5: 0 | G5: - | H5: Facebook Ads
A6: 3 | B6: Snippet 2 | C6: 0 | G6: - | H6: Facebook Ads
A7: 4 | B7: Snippet 3 | C7: 0 | G7: - | H7: Facebook Ads
A8: 5 | B8: Snippet 4 | C8: 0 | G8: - | H8: Facebook Ads
A9: 6 | B9: Snippet 5 | C9: 0 | G9: - | H9: Facebook Ads
A10: 7 | B10: Snippet 6 | C10: 0 | G10: - | H10: Facebook Ads
A11: 8 | B11: Snippet 7 | C11: 0 | G11: - | H11: Facebook Ads
A12: 9 | B12: Snippet 8 | C12: 0 | G12: - | H12: Facebook Ads
A13: 10 | B13: Snippet 9 | C13: 0 | G13: - | H13: Facebook Ads
A14: 11 | B14: Snippet 10 | C14: 0 | G14: - | H14: Facebook Ads
A15: 12 | B15: Teaser 1 | C15: 0 | G15: - | H15: Website
... A22: 19 | B22: Warmup: Relax Your Body, Free Your Mind – Mike Chang | C22: 0 | G22: - | H22: Website & Kajabi
B23: Course Content | C23: =SUM(C24:C33) | D23: =SUM(D24:D33) | E23: =SUM(E24:E33)
A24: 1 | B24: D_Adam Roa_flow-cc-s7 | C24: 0.02494213 | D24: 4926 | E24: 26142 | F24: 1 male | G24: - | H24: Website & Kajabi
A25: 2 | B25: D_Alberto Villoldo_flow-cc-s7 | C25: 0.021770833 | D25: 3620 | E25: 19757 | F25: 1 male | G25: - | H25: Website & Kajabi
A26: 3 | B26: D_Anita Moorjani_flow-cc-s7 | C26: 0.028263889 | D26: 4443 | E26: 23154 | F26: 1 female | G26: flow-cc-s6 | H26: Website & Kajabi
A27: 4 | B27: D_Bruce Lipton_flow-cc-s7 | C27: 0.044027778 | D27: 9783 | E27: 52692 | F27: 1 male, 1 female | G27: - | H27: Website & Kajabi
A28: 5 | B28: D_Byron Katie Interview_flow-cc-s7 | C28: 0.034108796 | D28: 5851 | E28: 30909 | F28: 2 females | G28: flow-cc-s4 | H28: Website & Kajabi
A29: 6 | B29: D_Daniel Alan_flow-cc-s7 | C29: 0.028923611 | D29: 4256 | E29: 24356 | F29: 1 male | G29: - | H29: Website & Kajabi
A30: 7 | B30: D_Deva Premal & Miten_flow-cc-s7 | C30: 0.016435185 | D30: 1711 | E30: 9263 | F30: 1 male, 1 female | G30: prd-cc-k1 | H30: Website & Kajabi
A31: 8 | B31: D_Dr Alex loyd_flow-cc-s7 | C31: 0.020185185 | D31: 3748 | E31: 20773 | F31: 1 male | G31: mtg-cc-s1 | H31: Website & Kajabi
A32: 9 | B32: D_Dr Bradley Nelson_flow-cc-s7 | C32: 0.012141204 | D32: 2686 | E32: 15737 | F32: 1 male | G32: - | H32: Website & Kajabi
A33: 10 | B33: D_Dr Eric Pearl_flow-cc-s7 | C33: 0.023032407 | D33: 3784 | E33: 21068 | F33: 1 male | G33: - | H33: Website & Kajabi
A34: 11 | B34: D_Dr Gabor Maté_flow-cc-s7 | C34: 0.069780093 | D34: 13703 | E34: 72556 | F34: 4 male, 9 female | G34: - | H34: Website & Kajabi
A35: 12 | B35: D_Dr Joe Dispenza Interview_flow-cc-s7 | C35: 0.027662037 | D35: 5494 | E35: 32023 | F35: 1 male, 1 female | G35: - | H35: Website & Kajabi
... A61: 38 | B61: D_Eckhart Tolle_flow-cc-s7 | C61: 0.021354167 | D61: 2885 | E61: 31991 | F61: 1 male | G61: - | H61: Website & Kajabi
A62: 39 | B62: D_Andreas Goldemann_flow-cc-s7 | C62: 0.027453704 | D62: flo | F62: 1 male | G62: - | H62: Website & Kajabi
B63: Bonus Content | C63: =SUM(C64:C67) | D63: =SUM(D64:D67) | E63: =SUM(E64:E67)
A64: 40 | B64: Louise Hay – You can Heal Your Life | C64: 0 | H64: Kajabi
A65: 41 | B65: Alex Loyd – The Psychology of Disease | C65: 0 | H65: Kajabi
A66: 42 | B66: Matt Cooke – You are always in a state of manifestation | C66: 0 | H66: Kajabi
A67: 43 | B67: Bruce Lipton & Gregg Braden – Humanity in the Age of Technology | C67: 0 | H67: Kajabi
A68: 44 | B68: "Tuning into new potentials" - Foundations course with Dr Joe Dispenza | C68: 0 | H68: Kajabi
A69: 45 | B69: Sound Healing Frequencies | Deep Relaxation | Chakra Healing (long version) | C69: 0 | D69: - | E69: - | F69: - | G69: - | H69: Kajabi
A70: 46 | B70: Bonus 1 – Local Speaker | C70: 0 | G70: - | H70: Kajabi
A71: 47 | B71: Bonus 2 – Local Speaker | C71: 0 | G71: - | H71: Kajabi
...

Sheet Emails
D1: Optin / Warm Up | E1: Free Funnel | F1: Sales
C2: Optin phase | D2: Start Opt In | E2: Start Summit | F2: Start Sales | G2: End of Sales
C3: 2 weeks | D3: =Intro!A6 | E3: =Intro!C7 | F3: =Intro!C8 | G3: =Intro!C9
B4: # | C4: Category | D4: Email name (AC) | E4: Countdown (T-X) | F4: Date | G4: Video Link (if applicable) | H4: Active Campain Link (Blueprint)
B5: 1 | C5: optin phase | D5: optin1 | E5: -14 | F5: =$E$3+Table85[[#This Row],[Countdown (T-X)]] | H5: https://psionline.activehosted.com/series/23608
B6: 2 | C6: optin phase | D6: optin2 | E6: -11 | F6: =$E$3+Table85[[#This Row],[Countdown (T-X)]] | H6: https://psionline.activehosted.com/series/23608
B7: 3 | C7: optin phase | D7: optin3 | E7: -6 | F7: =$E$3+Table85[[#This Row],[Countdown (T-X)]] | H7: https://psionline.activehosted.com/series/23608
B8: 4 | C8: optin phase | D8: optin4 | E8: -3 | F8: =$E$3+Table85[[#This Row],[Countdown (T-X)]] | H8: https://psionline.activehosted.com/series/23608
B9: 5 | C9: optin phase | D9: optin5 | E9: 0 | F9: =$E$3+Table85[[#This Row],[Countdown (T-X)]] | H9: https://psionline.activehosted.com/series/23608
B10: 6 | C10: warmup phase | D10: warmup1 | E10: -10 | F10: =$E$3+Table85[[#This Row],[Countdown (T-X)]] | H10: https://psionline.activehosted.com/series/23610
B11: 7 | C11: warmup phase | D11: warmup2 | E11: -7 | F11: =$E$3+Table85[[#This Row],[Countdown (T-X)]] | H11: https://psionline.activehosted.com/series/23610
B12: 8 | C12: warmup phase | D12: warmup3 | E12: -4 | F12: =$E$3+Table85[[#This Row],[Countdown (T-X)]] | H12: https://psionline.activehosted.com/series/23610
B13: 9 | C13: after optin | D13: Welcome | E13: N/A | H13: https://psionline.activehosted.com/series/23609
B14: 10 | C14: day 0 | D14: Tomorrow we start | E14: -1 | F14: =$E$3+Table85[[#This Row],[Countdown (T-X)]] | H14: https://psionline.activehosted.com/series/23609
B15: 11 | C15: day 1 | D15: Day 1 | E15: 0 | F15: =$E$3+Table85[[#This Row],[Countdown (T-X)]] | H15: https://psionline.activehosted.com/series/23609
B16: 12 | C16: day 1 | D16: How was it? / Teaser | E16: 0 | F16: =$E$3+Table85[[#This Row],[Countdown (T-X)]] | H16: https://psionline.activehosted.com/series/23609
B17: 13 | C17: day 2 | D17: Day 2 | E17: 1 | F17: =$E$3+Table85[[#This Row],[Countdown (T-X)]] | H17: https://psionline.activehosted.com/series/23609
B18: 14 | C18: day 3 | D18: Day 3 | E18: 2 | F18: =$E$3+Table85[[#This Row],[Countdown (T-X)]] | H18: https://psionline.activehosted.com/series/23609
B19: 15 | C19: day 3 | D19: Sales 1 | E19: 2 | F19: =$E$3+Table85[[#This Row],[Countdown (T-X)]] | H19: https://psionline.activehosted.com/series/23609
B20: 16 | C20: day 4 | D20: Day 4 | E20: 3 | F20: =$E$3+Table85[[#This Row],[Countdown (T-X)]] | H20: https://psionline.activehosted.com/series/23609
B21: 17 | C21: day 5 | D21: Day 5 | E21: 4 | F21: =$E$3+Table85[[#This Row],[Countdown (T-X)]] | H21: https://psionline.activehosted.com/series/23609
B22: 18 | C22: day 5 | D22: Sales 2 | E22: 4 | F22: =$E$3+Table85[[#This Row],[Countdown (T-X)]] | H22: https://psionline.activehosted.com/series/23609
B23: 19 | C23: day 6 | D23: Day 6 | E23: 5 | F23: =$E$3+Table85[[#This Row],[Countdown (T-X)]] | H23: https://psionline.activehosted.com/series/23609
B24: 20 | C24: day 7 | D24: Day 7 | E24: 6 | F24: =$E$3+Table85[[#This Row],[Countdown (T-X)]] | H24: https://psionline.activehosted.com/series/23609
B25: 21 | C25: day 8 | D25: Vote Your Favorite Speaker + Sales 3 | E25: 7 | F25: =$E$3+Table85[[#This Row],[Countdown (T-X)]] | H25: https://psionline.activehosted.com/series/23609
... B29: 25 | C29: day 12 | D29: Sales 5 + Last Chance | E29: 12 | F29: =$E$3+Table85[[#This Row],[Countdown (T-X)]] | H29: https://psionline.activehosted.com/series/23609
B30: 26 | C30: after summit | D30: Welcome – Latecomers | E30: N/A | H30: https://psionline.activehosted.com/series/23609
B31: 27 | C31: after purchase | D31: Purchase Confirmation | E31: N/A | H31: https://psionline.activehosted.com/series/23612

Sheet Website Links
D1: Optional | E1: Optin / Warm Up | F1: PLC/ MC / Summit | G1: Sales | H1: Sales | I1: Sales
C2: Enter Domain below | D2: Date to be adjusted based on open rate | E2: Beginnig of Promotion (BoP) | F2: Start of PLC/ MC / Summit | G2: Beginning of Sales (BoS) | H2: End of Sales (EoS) | I2: End of extended Sales (EoeS)
C3: https://www.flowsummitespanol.com/ | E3: =Intro!C6 | F3: =Intro!C7 | G3: =Intro!C8 | H3: =Intro!C9 | I3: =Intro!C10
B4: page # | C4: website intern/slug | D4: URL | E4: Link Video File - Template | F4: Link Video File - Actual | G4: Intern Notes | H4: YOAST SEO PAGETITEL
B5: 1 | D5: =$C$3&Table114[[#This Row],[website intern/slug]] | H5: k1
B6: 2 | C6: optin/ | D6: =$C$3&Table114[[#This Row],[website intern/slug]] | G6: Double Optin | H6: Sign up - Summit
B7: 3a | C7: optin-confirmation/ | D7: =$C$3&Table114[[#This Row],[website intern/slug]] | G7: Redirect after Mail confirmation | H7: Confirm Registration
B8: 3b | C8: optin-successful/?NLS=1 | D8: =$C$3&Table114[[#This Row],[website intern/slug]] | H8: Registration Successful
B9: 4 | C9: offer/ | D9: =$C$3&Table114[[#This Row],[website intern/slug]] | H9: Limited Offer
B10: 5 | C10: offer-thank-you/ | D10: =$C$3&Table114[[#This Row],[website intern/slug]] | H10: Purchase Confirmation
B11: 6 | C11: contact/ | D11: =$C$3&Table114[[#This Row],[website intern/slug]] | H11: Contact
B12: 7 | C12: legal-notice-privacy-policy/ | D12: =$C$3&Table114[[#This Row],[website intern/slug]] | G12: 404 Plugin | H12: Privacy Policy
B13: 8 | C13: 404-2/ | D13: =$C$3&Table114[[#This Row],[website intern/slug]] | G13: Redirection if Access is wanted and denialed | H13: Content Not Found
B14: 9 | C14: not-yet-registered/ | D14: =$C$3&Table114[[#This Row],[website intern/slug]] | H14: Not Registered
B15: 10 | C15: vision-and-mission/ | D15: =$C$3&Table114[[#This Row],[website intern/slug]] | H15: Our Values
B16: 11 | C16: about-us/ | D16: =$C$3&Table114[[#This Row],[website intern/slug]] | G16: Single Optin | H16: About Us
B17: 12 | C17: affiliates/ | D17: =$C$3&Table114[[#This Row],[website intern/slug]] | G17: Approval Process started | H17: Affiliate Program
B18: 12a | C18: affiliates-confirmation/ | D18: =$C$3&Table114[[#This Row],[website intern/slug]] | G18: Approval confirmed | H18: Registration Successful
B19: 12b | C19: affiliates-successful/ | D19: =$C$3&Table114[[#This Row],[website intern/slug]] | G19: Upsale | H19: Welcome
B20: 13 | C20: snippet-1/ | D20: =$C$3&Table114[[#This Row],[website intern/slug]] | H20: Preview 1
B21: 14 | C21: snippet-2/ | D21: =$C$3&Table114[[#This Row],[website intern/slug]] | H21: Preview 2
B22: 15 | C22: snippet-3/ | D22: =$C$3&Table114[[#This Row],[website intern/slug]] | H22: Preview 3
B23: X | C23: day-1/?NLS=1 | D23: =$C$3&Table114[[#This Row],[website intern/slug]] | H23: Day 1
B24: X | C24: day-2/?NLS=1 | D24: =$C$3&Table114[[#This Row],[website intern/slug]] | H24: Day 2
B25: X | C25: day-3/?NLS=1 | D25: =$C$3&Table114[[#This Row],[website intern/slug]] | H25: Day 3
B26: X | C26: day-4/?NLS=1 | D26: =$C$3&Table114[[#This Row],[website intern/slug]] | H26: Day 4
B27: X | C27: day-5/?NLS=1 | D27: =$C$3&Table114[[#This Row],[website intern/slug]] | H27: Day 5
C28: day-6/?NLS=1 | D28: =$C$3&Table114[[#This Row],[website intern/slug]]
C29: day-7/?NLS=1 | D29: =$C$3&Table114[[#This Row],[website intern/slug]]
C30: bonus-1-wisdom/?NLS=1 | D30: =$C$3&Table114[[#This Row],[website intern/slug]]
C31: bonus-1-health/?NLS=1 | D31: =$C$3&Table114[[#This Row],[website intern/slug]]
C32: bonus-1-manifest/?NLS=1 | D32: =$C$3&Table114[[#This Row],[website intern/slug]]
C33: bonus-2/?NLS=1 | D33: =$C$3&Table114[[#This Row],[website intern/slug]]
B34: X | C34: my-videos/?NLS=1 | D34: =$C$3&Table114[[#This Row],[website intern/slug]] | H34: My Active Videos

Sheet Graphics
D1: For partners / freelancers: please fill in
B2: Subcategory | C2: Original language | D2: Translated Language | E2: Sidenote | F2: BP Folder Location
B3: Website Graphics
B4: Global (Menu-Links) | C4: Legal notice and privacy policy | F4: SP Folder - Website graphics
B5: Global (Menu-Links) | C5: Contact
B6: Global (Menu-Links) | C6: Login
B7: Global (Menu-Links) | C7: Vision and mission
B8: Global (Menu-Links) | C8: About us
B9: Global (Menu-Links) | C9: Affiliates
B10: Global (Menu-Links) | C10: Book now!
B11: Footer | C11: Links
B12: Footer | C12: Follow us!
B13: Footer | C13: Stay tuned and never miss a any of our upcoming courses and summits
B14: Form | C14: I accept the privacy policy and that by registering I will receive awesome offers and communication from younity and "company name" through the newsletter. Your data will kept confidential and not disclosed to third parties. | E14: Please mark the word [privacy policy] so that it can be linked to the privacy policy page
B15: Theme Customizer | C15: The Work [Country] | E15: Please use same Translation as for the Logo Title
B16: Theme Customizer | C16: with Byron Katie
B17: Countdown | C17: The online course starts on [Date]! Only:
B18: Buttons Sale | C18: Sign Up Now!
B19: Buttons Sale | C19: Claim your special offer!
B20: Buttons Sale | C20: Join us!
B21: Buttons Sale | C21: Pay in Installments
B22: Optin Arrow Graphic | C22: For a limited time
B23: Offer Arrow Graphic | C23: Limited time offer!
B24: Button Optin | C24: Sign in now
B25: Share Buttons Text | C25: Happiness is the only thing that doubles when you share it. Share this free content with your friends!
B26: Speaker Name | C26: Byron Katie
B27: Graphic Offer Mockup | C27: Get your full Bundle now!
... B30: Graphic Thumbnail | C30: Recording
B37: All the rest of the graphics are in Canva and Country Leads can localize them directly there. Please remember to always make copies of the blueprint designs.
B38: Category | C38: Link in Canva | D38: Notes
B39: Email Graphics | C39: https://www.canva.com/folder/FAHDknipACE
B40: Worksheets | C40: https://www.canva.com/folder/FAHDj9YEcQs
B41: PPC Graphics | C41: https://www.canva.com/folder/FAHDpv62w_o
B42: Snippet End Cards

Sheet Facebook Text
B1: What (Graphic / Text) | C1: Original language | D1: Translated language | E1: Original Language2 | F1: Translated Round 2 | G1: Original Language3 | H1: Translated Round 3 | I1: Graphics Copy
B3: AD SET 1 — Problem Aware — "The Feeling You Can't Name" | C3: ROUND 1 | E3: ROUND 2 | G3: ROUND 3 | I3: ROUND 1
B4: Meta Description | C4: 7 days. 38+ world-renowned teachers. Free. Join 150,000+ people and finally find the words for what you're feeling.
C5: 1a | E5: 1.1a | I5: 1a
B6: Meta Headline 1 | C6: The feeling you can't explain
B7: Meta Headline 2 | C7: 7 days to finally change it — free
B8: Meta Text | C8: There's a feeling that's hard to explain to anyone. From the outside, your life is fine. But somewhere underneath, there's a quiet weight you carry — a sense that the real version of you is just out of reach. You've tried to shake it. Read the books, done the meditations. Sometimes things shift for a week. Then the weight comes back. You are not broken. That feeling is not a malfunction — it is a call. 7 days. 38 transformative teachers. The flow! summit 2026. 100% free. Register now. | I8: Graphic Title: You Are Not Broken. You Are Just Disconnected. Graphic Pre-header: flow! summit: 7 free days to restore the connection. Graphic CTA: Start Reconnecting Now
C9: 1b | E9: 1.1b | I9: 1b
B10: Meta Headline 1 | C10: You know something's missing
B11: Meta Headline 2 | C11: 38 teachers. 7 days. Free.
B12: Meta Text | C12: You wake up tired of being tired. You go through the motions. You smile when you're supposed to. But at 2am, when it's quiet, you know something is off. Not broken. Not depressed. Just... not alive in the way you know you could be. That gap between who you are and who you sense you're meant to be — it has a path. 38 of the world's greatest teachers. 7 days. Completely free. The flow! summit 2026. Register free. The journey starts where you are. | I12: Graphic Title: Every Day You Delay, the Distance Grows. Graphic Pre-header: You have felt this long enough. 7 free days to change it. Graphic CTA: Close the Gap Today
C13: 1c | E13: 1.1c | I13: 1c
B14: Meta Headline 1 | C14: Still searching. Still stuck. Why?
B15: Meta Headline 2 | C15: The answer is a 7-day free summit
B16: Meta Text | C16: What if what you've been searching for isn't more information? You've done the reading. You've felt moments of clarity that faded by morning. And you're still carrying the same weight you started with. The missing piece is almost never more knowledge. It is guided experience. A structure that takes you somewhere. For 7 days, the flow! summit brings together 38 of the world's most extraordinary teachers in one free, progressive journey — from where you are to where you want to be. Register free. | I16: Graphic Title: Stop Searching Alone. Start the Journey Together. Graphic Pre-header: 38 World-Renowned Teachers. 7 Days. Free. Graphic CTA: Join Free Now
B18: AD SET 2 — Solution Aware / Most Aware — "38 Teachers. 0 Cost. The Event That Changes Everything." | C18: ROUND 1 | E18: ROUND 2 | G18: ROUND 3 | I18: ROUND 1
B19: Meta Description | C19: Dr. Joe Dispenza, Sadhguru, Eckhart Tolle, Dr. Gabor Maté, Bruce Lipton + 33 more. 7 days free. Register now.
C20: 2a | E20: 2.1a | I20: 2a
B21: Meta Headline 1 | C21: 38 teachers. 7 days. 0 cost.
B22: Meta Headline 2 | C22: The biggest spiritual event of 2026
B23: Meta Text | C23: Dr. Joe Dispenza. Eckhart Tolle. Bruce Lipton. Sadhguru. Dr. Gabor Maté. Anita Moorjani. Gregg Braden. Neale Donald Walsch. Byron Katie. Nine of the most transformative people alive — sharing the same stage. Then add 29 more. 38 teachers. 7 days. One free event structured as a day-by-day arc from resetting your nervous system to discovering your quantum self. 150,000 people participated last year. Zero cost. Full access. Register free now. This is the one you've been waiting for. | I23: Graphic Title: One Stage. Dispenza. Tolle. Sadhguru. Thirty-Five More. Graphic Pre-header: 7 days of live wisdom that could shift everything. Graphic CTA: Unlock the Full Lineup
C24: 2b | E24: 2.1b | I24: 2b
B25: Meta Headline 1 | C25: 150,000 joined last year. Your turn.
B26: Meta Headline 2 | C26: 38 teachers. 1 free event. Join now.
B27: Meta Text | C27: Last year, 150,000 people changed their lives during one free 7-day online event. This year, there's a seat for you. Dr. Joe Dispenza, Eckhart Tolle, Sadhguru, Bruce Lipton, Dr. Gabor Maté, Anita Moorjani, Gregg Braden, Byron Katie — and 30 more — all gathering in one place, for free. Seven days. Exclusive sessions. Original wisdom from the people who have shaped how millions of us understand healing and consciousness. This is it. Register free. | I27: Graphic Title: 150,000 People Found What They Were Missing. Graphic Pre-header: They found it at flow! summit. Registration is still open. Graphic CTA: Find It This Week
C28: 2c | E28: 2.1c | I28: 2c
B29: Meta Headline 1 | C29: Not another YouTube playlist
B30: Meta Headline 2 | C30: A 7-day journey. Free. Starting now.
B31: Meta Text | C31: You've seen their talks. You follow these teachers. So what makes the flow! summit different? These are brand-new sessions, created exclusively for this event — organized into a 7-day journey with a beginning, a middle, and an end. A structure that takes you somewhere, instead of leaving you inspired for a day and back to normal by Thursday. Day 1 resets your nervous system. Day 7, Dr. Joe Dispenza closes the summit. 38 teachers. All of it free. Register now. | I31: Graphic Title: Day 1 to Day 7 — A Journey That Actually Goes Somewhere Graphic Pre-header: flow! summit 2026 — 38 Teachers, 100% Free Graphic CTA: See the Full Lineup — Register Free
B33: AD SET 3 — Problem Aware — "The 7-Day Reset" (Body-First Entry Point) | C33: ROUND 1 | E33: ROUND 2 | G33: ROUND 3 | I33: ROUND 1
B34: Meta Description | C34: Stress. Exhaustion. A body that won't calm down. 7 days of world-class guidance to reset everything — free.
C35: 3a | E35: 3.1a | I35: 3a
B36: Meta Headline 1 | C36: Your body has been screaming. Listen.
B37: Meta Headline 2 | C37: 7 days to reset everything — free
B38: Meta Text | C38: Your shoulders have been tight for months. You wake up already tired. Your body is running on adrenaline it no longer has. This is what happens when your nervous system has been in emergency mode so long it's forgotten how to do anything else. The flow! summit begins exactly here. Day 1 is dedicated entirely to your body — conscious breathing, Qigong, sound healing. Practical tools to bring your system back to baseline. Then 7 days of the world's greatest teachers take you the rest of the way. Register free. | I38: Graphic Title: Start with Your Body. Transform Your Life. Graphic Pre-header: flow! summit 2026 — Day 1: Reset Your System Graphic CTA: Register Free — It Starts Here
C39: 3b | E39: 3.1b | I39: 3b
B40: Meta Headline 1 | C40: Your body knows something's wrong
B41: Meta Headline 2 | C41: 7 days of healing. Completely free.
B42: Meta Text | C42: When did "fine" start feeling like the most exhausting word in your vocabulary? There is a difference between surviving the day and actually living it — and your body knows exactly which one it's been doing. The tension that never quite releases. The mornings that take longer to start. What if 7 days could change that — not by adding more to your life, but by giving your system permission to release what it's been holding? The flow! summit 2026. 38 teachers. 7 days. 100% free. Register now. | I42: Graphic Title: The Reset Your Body Has Been Asking For Graphic Pre-header: flow! summit 2026 — Starts with Day 1: Reset Your System Graphic CTA: Begin Your Reset — Free
C43: 3c | E43: 3.1c | I43: 3c
...

Sheet Facebook Snippets
B3: Number | C3: Snippets Downloadlinks: | D3: Snippet Name in Dropbox | E3: Text Overlay (original) | F3: Text Overlay (translated)
B4: 1
B5: 2
B6: 3
B7: 4
B8: 5
B9: 6
B10: 7
B11: 8
B12: 9
B13: 10
B15: Link to BP Canva Folder: | D15: Linked to Translated Canva Graphics:
C18: If you want the snippets localized, follow these steps:
C19: 1. Download the snippet SRTs and translate them
C20: 2. Copy the Blueprint Snippet End Cards to your local folder and translate them
C21: 3. Translate the Text Overlay you can find above in your local Translation Sheet
C22: 4. Send an email with a Snippet Localization Request to achilleasmz@gmail.com (keep mihai@younity.com in cc): a) attach your translated snippet SRTs b) add the link to your Canva folder with translated Snippet End Cards c) add the link to your local Translation Sheet with your PPC Snippets tab translated d) add the link to your local Dropbox folder where the final videos will be uploaded e) provide your deadline - by when you need the snippets ready

Sheet 6 Facebook Snippets
B2: Watch Video here-> https://www.loom.com/share/efed106913f743739fc4548079fd8520 | D2: Dear tranlsator: Please share with Polina Batishcheva batishchevap@gmail.com
B3: Number: | C3: Snippets Downloadlinks: | D3: Snippet Title (original) | E3: Snippet Title (translated)
B4: 1.
B5: 2.
B6: 3.
B7: 4.
B8: 5.
B10: Number: | C10: Call to Action (original) | D10: Call to Action (translated) | E10: Spalte1

Sheet 10) Upviral (optional)
B1: Original | C1: Translated
A2: Main
A3: Title | B3: Send email right after registration
A4: Subject Line | B4: Thank you for signing up, {{name}}!
A5: Text | B5: Thank you for signing up for our campaign, {{name}}! You have: {{total_points}} points. Your unique referral URL is: {{referral_url}} Share this link with your friends to get more points. Thank you!
A6: Main
A7: Title | B7: Send email on referral link signup
A8: Subject Line | B8: {{name}}, someone signed up through your referral link!
A9: Text | B9: Great news, {{name}} — someone just signed up through your referral link! You have: {{total_points}} points. Your unique referral URL is: {{referral_url}} Keep sharing this link with your friends to get more points. Thank you!
A10: Incetives
A11: Title | B11: Send email when a Incentive "Your free video" is unlocked
A12: Subject Line | B12: {{name}}, you just unlocked a reward: {{reward_name}}!
A13: Text | B13: Awesome news, {{name}}. You just unlocked: {{reward_name}} To view the reward go to: {{reward_url}} You have {{points_to_unlock}} points left to unlock the next reward. Keep sharing your unique referral link with your friends to get more points. Your unique referral URL is: {{referral_url}} Thank you!

Sheet UTM Links
B1: Domain
B2: https://www.flowsummitespanol.com/
B3: Area | C3: Slug | D3: Target Link (original) | E3: Utm_source | F3: Utm_medium | G3: Utm_campaign | H3: UTM Link | I3: Shortened URL : Use Bit.ly to create a short UTM Link | J3: Note:
B4: Optin mail 1 | C4: optin/ | D4: =$B$2&C4 | E4: activecampaign | F4: email | G4: optin1 | H4: =_xlfn.CONCAT(D4,"?utm_source=",E4,"&utm_medium=",F4,"&utm_campaign=",G4) | J4: If split testing please create additional UTM's with optin1a and optin1b as your campaign names
B5: Optin mail 2 | C5: optin/ | D5: =$B$2&C5 | E5: activecampaign | F5: email | G5: optin2 | H5: =_xlfn.CONCAT(D5,"?utm_source=",E5,"&utm_medium=",F5,"&utm_campaign=",G5)
B6: Optin mail 3 | C6: optin/ | D6: =$B$2&C6 | E6: activecampaign | F6: email | G6: optin3 | H6: =_xlfn.CONCAT(D6,"?utm_source=",E6,"&utm_medium=",F6,"&utm_campaign=",G6)
B7: Optin mail 4 | C7: optin/ | D7: =$B$2&C7 | E7: activecampaign | F7: email | G7: optin4 | H7: =_xlfn.CONCAT(D7,"?utm_source=",E7,"&utm_medium=",F7,"&utm_campaign=",G7)
B8: Optin mail 5 | C8: optin/ | D8: =$B$2&C8 | E8: activecampaign | F8: email | G8: optin5 | H8: =_xlfn.CONCAT(D8,"?utm_source=",E8,"&utm_medium=",F8,"&utm_campaign=",G8)
B9: Optin mail 6 | C9: optin/ | D9: =$B$2&C9 | E9: activecampaign | F9: email | G9: optin6 | H9: =_xlfn.CONCAT(D9,"?utm_source=",E9,"&utm_medium=",F9,"&utm_campaign=",G9)
B10: Warmup mails | C10: optin/ | D10: =$B$2&C10 | E10: activecampaign | F10: email | G10: warmup | H10: =_xlfn.CONCAT(D10,"?utm_source=",E10,"&utm_medium=",F10,"&utm_campaign=",G10) | J10: We add this to the share with friends links
B11: FB Lead Gen | C11: optin/ | D11: =$B$2&C11 | E11: facebook | F11: cpc | G11: =Intro!$C$14 | H11: =_xlfn.CONCAT(D11,"?utm_source=",E11,"&utm_medium=",F11,"&utm_campaign=",G11) | J11: Please update yelow highlight with localized course code
B12: Facebook Group Optin | C12: optin/ | D12: =$B$2&C12 | E12: facebook | F12: group | G12: fbgroup-optin | H12: =_xlfn.CONCAT(D12,"?utm_source=",E12,"&utm_medium=",F12,"&utm_campaign=",G12)
B13: Facebook Page Optin | C13: optin/ | D13: =$B$2&C13 | E13: facebook | F13: page | G13: fbpage-optin | H13: =_xlfn.CONCAT(D13,"?utm_source=",E13,"&utm_medium=",F13,"&utm_campaign=",G13)
B14: Insta Profile Link | C14: optin/ | D14: =$B$2&C14 | E14: instagram | F14: profile | G14: insta-optin | H14: =_xlfn.CONCAT(D14,"?utm_source=",E14,"&utm_medium=",F14,"&utm_campaign=",G14)
B15: Insta Story Link | C15: optin/ | D15: =$B$2&C15 | E15: instagram | F15: story | G15: insta-optin | H15: =_xlfn.CONCAT(D15,"?utm_source=",E15,"&utm_medium=",F15,"&utm_campaign=",G15)
B16: Telegram Optin | C16: optin/ | D16: =$B$2&C16 | E16: telegram | F16: channel | G16: telegram-optin | H16: =_xlfn.CONCAT(D16,"?utm_source=",E16,"&utm_medium=",F16,"&utm_campaign=",G16)
B17: Youtube Optin | C17: optin/ | D17: =$B$2&C17 | E17: youtube | F17: video | G17: youtube-optin | H17: =_xlfn.CONCAT(D17,"?utm_source=",E17,"&utm_medium=",F17,"&utm_campaign=",G17)
B18: Offer Mail - Sales 1 | C18: offer/ | D18: =$B$2&C18 | E18: activecampaign | F18: email | G18: sales1 | H18: =_xlfn.CONCAT(D18,"?utm_source=",E18,"&utm_medium=",F18,"&utm_campaign=",G18)
B19: Offer Mail - Sales 2 | C19: offer/ | D19: =$B$2&C19 | E19: activecampaign | F19: email | G19: sales2 | H19: =_xlfn.CONCAT(D19,"?utm_source=",E19,"&utm_medium=",F19,"&utm_campaign=",G19)
B20: Offer Mail - Sales 3 | C20: offer/ | D20: =$B$2&C20 | E20: activecampaign | F20: email | G20: sales3 | H20: =_xlfn.CONCAT(D20,"?utm_source=",E20,"&utm_medium=",F20,"&utm_campaign=",G20)
B21: Offer Mail - Sales 4 | C21: offer/ | D21: =$B$2&C21 | E21: activecampaign | F21: email | G21: sales4 | H21: =_xlfn.CONCAT(D21,"?utm_source=",E21,"&utm_medium=",F21,"&utm_campaign=",G21)
B22: Offer Mail - Sales 5 | C22: offer/ | D22: =$B$2&C22 | E22: activecampaign | F22: email | G22: sales5 | H22: =_xlfn.CONCAT(D22,"?utm_source=",E22,"&utm_medium=",F22,"&utm_campaign=",G22)
B23: Offer Mail - Sales 6 | C23: offer/ | D23: =$B$2&C23 | E23: activecampaign | F23: email | G23: sales6 | H23: =_xlfn.CONCAT(D23,"?utm_source=",E23,"&utm_medium=",F23,"&utm_campaign=",G23)
B24: Offer Mail - Sales 7 | C24: offer/ | D24: =$B$2&C24 | E24: activecampaign | F24: email | G24: sales7 | H24: =_xlfn.CONCAT(D24,"?utm_source=",E24,"&utm_medium=",F24,"&utm_campaign=",G24)
B25: FB Remarketing | C25: offer/ | D25: =$B$2&C25 | E25: facebook | F25: cpc | G25: =G11 | H25: =_xlfn.CONCAT(D25,"?utm_source=",E25,"&utm_medium=",F25,"&utm_campaign=",G25) | J25: Please update yelow highlight with localized course code
B26: Facebook Group Offer | C26: offer/ | D26: =$B$2&C26 | E26: facebook | F26: group | G26: fbgroup-offer | H26: =_xlfn.CONCAT(D26,"?utm_source=",E26,"&utm_medium=",F26,"&utm_campaign=",G26)
B27: Facebook Page Offer | C27: offer/ | D27: =$B$2&C27 | E27: facebook | F27: page | G27: fbpage-offer | H27: =_xlfn.CONCAT(D27,"?utm_source=",E27,"&utm_medium=",F27,"&utm_campaign=",G27)
B28: Insta Offer | C28: offer/ | D28: =$B$2&C28 | E28: instagram | F28: profile | G28: insta-offer | H28: =_xlfn.CONCAT(D28,"?utm_source=",E28,"&utm_medium=",F28,"&utm_campaign=",G28)
B29: Insta Offer | C29: offer/ | D29: =$B$2&C29 | E29: instagram | F29: story | G29: insta-offer | H29: =_xlfn.CONCAT(D29,"?utm_source=",E29,"&utm_medium=",F29,"&utm_campaign=",G29)
B30: telegram Offer | C30: offer/ | D30: =$B$2&C30 | E30: telegram | F30: channel | G30: telegram-offer | H30: =_xlfn.CONCAT(D30,"?utm_source=",E30,"&utm_medium=",F30,"&utm_campaign=",G30)
B31: Youtube Offer | C31: offer/ | D31: =$B$2&C31 | E31: youtube | F31: video | G31: youtube-offer | H31: =_xlfn.CONCAT(D31,"?utm_source=",E31,"&utm_medium=",F31,"&utm_campaign=",G31)

Sheet Tag Generator
A2: Project code | B2: flow-cc-s7-l1 | E2: Tag | F2: Prefix | G2: Infix | H2: Postfix
A3: Bundle Product | D3: General | E3: =IF(COUNTBLANK(F3)=1,"",F3&"-")&$B$2&IF(COUNTBLANK(G3)=1,"","-"&G3)&IF(COUNTBLANK(H3)=1,"","-"&H3) | F3: optin
E4: =IF(COUNTBLANK(F4)=1,"",F4&"-")&$B$2&IF(COUNTBLANK(G4)=1,"","-"&G4)&IF(COUNTBLANK(H4)=1,"","-"&H4) | F4: optin | H4: org
E5: =IF(COUNTBLANK(F5)=1,"",F5&"-")&$B$2&IF(COUNTBLANK(G5)=1,"","-"&G5)&IF(COUNTBLANK(H5)=1,"","-"&H5) | F5: optin | H5: ppc
E6: =IF(COUNTBLANK(F6)=1,"",F6&"-")&$B$2&IF(COUNTBLANK(G6)=1,"","-"&G6)&IF(COUNTBLANK(H6)=1,"","-"&H6) | F6: interested
A7: 1) Insert Bundle product | E7: =IF(COUNTBLANK(F7)=1,"",F7&"-")&$B$2&IF(COUNTBLANK(G7)=1,"","-"&G7)&IF(COUNTBLANK(H7)=1,"","-"&H7) | F7: not-interested
A8: 2) Copy all needed tags | E8: =IF(COUNTBLANK(F8)=1,"",F8&"-")&$B$2&IF(COUNTBLANK(G8)=1,"","-"&G8)&IF(COUNTBLANK(H8)=1,"","-"&H8) | F8: purchase
A9: 3) Past them in AC (Contacts --> Tags --> Add Tags) | E9: =IF(COUNTBLANK(F9)=1,"",F9&"-")&$B$2&IF(COUNTBLANK(G9)=1,"","-"&G9)&IF(COUNTBLANK(H9)=1,"","-"&H9) | F9: tracked
E10: =IF(COUNTBLANK(F10)=1,"",F10&"-")&$B$2&IF(COUNTBLANK(G10)=1,"","-"&G10)&IF(COUNTBLANK(H10)=1,"","-"&H10) | F10: refund
E11: =IF(COUNTBLANK(F11)=1,"",F11&"-")&$B$2&IF(COUNTBLANK(G11)=1,"","-"&G11)&IF(COUNTBLANK(H11)=1,"","-"&H11) | F11: abandoned
D12: MC | E12: =IF(COUNTBLANK(F12)=1,"",F12&"-")&$B$2&IF(COUNTBLANK(G12)=1,"","-"&G12)&IF(COUNTBLANK(H12)=1,"","-"&H12) | F12: attended
E13: =IF(COUNTBLANK(F13)=1,"",F13&"-")&$B$2&IF(COUNTBLANK(G13)=1,"","-"&G13)&IF(COUNTBLANK(H13)=1,"","-"&H13) | F13: leftearly
E14: =IF(COUNTBLANK(F14)=1,"",F14&"-")&$B$2&IF(COUNTBLANK(G14)=1,"","-"&G14)&IF(COUNTBLANK(H14)=1,"","-"&H14) | F14: missed
E15: =IF(COUNTBLANK(F15)=1,"",F15&"-")&$B$2&IF(COUNTBLANK(G15)=1,"","-"&G15)&IF(COUNTBLANK(H15)=1,"","-"&H15) | F15: easyweb missing
E16: =IF(COUNTBLANK(F16)=1,"",F16&"-")&$B$2&IF(COUNTBLANK(G16)=1,"","-"&G16)&IF(COUNTBLANK(H16)=1,"","-"&H16) | F16: unconfirmed | H16: org
E17: =IF(COUNTBLANK(F17)=1,"",F17&"-")&$B$2&IF(COUNTBLANK(G17)=1,"","-"&G17)&IF(COUNTBLANK(H17)=1,"","-"&H17) | F17: unconfirmed | H17: ppc
D18: Direct Optin | E18: =IF(COUNTBLANK(F18)=1,"",F18&"-")&$B$2&IF(COUNTBLANK(G18)=1,"","-"&G18)&IF(COUNTBLANK(H18)=1,"","-"&H18) | H18: optin 1 clickers
E19: =IF(COUNTBLANK(F19)=1,"",F19&"-")&$B$2&IF(COUNTBLANK(G19)=1,"","-"&G19)&IF(COUNTBLANK(H19)=1,"","-"&H19) | H19: optin 2 clickers
E20: =IF(COUNTBLANK(F20)=1,"",F20&"-")&$B$2&IF(COUNTBLANK(G20)=1,"","-"&G20)&IF(COUNTBLANK(H20)=1,"","-"&H20) | H20: optin 3 clickers
E21: =IF(COUNTBLANK(F21)=1,"",F21&"-")&$B$2&IF(COUNTBLANK(G21)=1,"","-"&G21)&IF(COUNTBLANK(H21)=1,"","-"&H21) | H21: optin 4 clickers
D22: Bundle | E22: =F22&"-"&LEFT($B$3,LEN($B$3)-3)&IF(COUNTBLANK(G22)=1,"","-"&G22)&IF(COUNTBLANK(H22)=1,"","-"&H22) | F22: purchase | G22: bundle | H22: =B2
E23: =F23&"-"&LEFT($B$3,LEN($B$3)-3)&IF(COUNTBLANK(G23)=1,"","-"&G23)&IF(COUNTBLANK(H23)=1,"","-"&H23) | F23: refund | G23: bundle | H23: =B3

Sheet (data validation)
D2: Status Translation
C3: Stages Web Graphics | D3: Not started | H3: Email Scheduled/ sent? | I3: Platform
C4: Optin | D4: In progress | F4: Yes | H4: 1-wfr/qm | I4: Website
C5: Sales | D5: Translation & QM Completed | F5: No | H5: 2-scheduled | I5: Website & Kajabi
F6: DO NOT TRANSLATE | H6: 3-sent | I6: Kajabi
I7: Facebook Ads
I8: Social Media
